Workbook
Name IQ_CH: 110000
Name IQ_CQ: 5000
Name IQ_CY: 10000
Name IQ_DAILY: 500000
Name IQ_FH: 100000
Name IQ_FQ: 500
Name IQ_FY: 1000
Name IQ_LTM: 2000
Name IQ_MONTH: 15000
Name IQ_NTM: 6000
Name IQ_WEEK: 50000
Name IQ_YTD: 3000

Sheet FSM Data Input_Empty
C2: ="Financial Statement Model for "&D5 -> Financial Statement Model for Apple
C3: $ in thousands except per share
C5: Company name | D5: Apple
C6: Ticker | D6: AAPL
C7: Circ break 1=off, 0=on | D7: 1
C8: Latest closing share price | D8: 299.24
C9: Latest closing share price date | D9: 43500
C10: Latest fiscal year end date | D10: 45947
C11: Shares outstanding (millions) | D11: 14776.353
C13: INCOME STATEMENT
C14: Fiscal year | D14: =E14-1 -> 2023 | E14: =F14-1 -> 2024 | F14: =YEAR(D10) -> 2025
C15: Fiscal year end date | D15: =EOMONTH(E15,-12) -> 45230 | E15: =EOMONTH(F15,-12) -> 45596 | F15: =D10 -> 45947
C17: Revenue | D17: 383285 | E17: 391035 | F17: 416161
C18: Cost of sales (enter as -) | D18: -214137 | E18: -210352 | F18: -220960
C19: Gross Profit | D19: =SUM(D17:D18) -> 169148 | E19: =SUM(E17:E18) -> 180683 | F19: =SUM(F17:F18) -> 195201
C20: Research & development (enter as -) | D20: -29915 | E20: -31370 | F20: -34550
C21: Selling, general & administrative (enter as -) | D21: -24932 | E21: -26097 | F21: -27601
C22: Operating profit (EBIT) | D22: =SUM(D19:D21) -> 114301 | E22: =SUM(E19:E21) -> 123216 | F22: =SUM(F19:F21) -> 133050
C23: Interest income | D23: 0 | E23: 0 | F23: 0
C24: Interest expense (enter as -) | D24: 0 | E24: 0 | F24: 0
C25: Other expense, net (enter as -) | D25: -565 | E25: 269 | F25: -321
C26: Pretax profit | D26: =SUM(D22:D25) -> 113736 | E26: =SUM(E22:E25) -> 123485 | F26: =SUM(F22:F25) -> 132729
C27: Taxes (enter expense as -) | D27: -16741 | E27: -29749 | F27: -20719
C28: Net income | D28: =SUM(D26:D27) -> 96995 | E28: =SUM(E26:E27) -> 93736 | F28: =SUM(F26:F27) -> 112010
C30: Depreciation & amortization | D30: 11519 | E30: 11445 | F30: 11698
C31: EBITDA | D31: =D30+D22 -> 125820 | E31: =E30+E22 -> 134661 | F31: =F30+F22 -> 144748
C32: Stock based compensation | D32: 10833 | E32: 11688 | F32: 12863
C33: Adjusted EBITDA | D33: =D31+D32 -> 136653 | E33: =E31+E32 -> 146349 | F33: =F31+F32 -> 157611
C35: Growth rates & margins
C36: Revenue growth | E36: =E17/D17-1 -> 0.020219941 | F36: =F17/E17-1 -> 0.064255118
C37: Gross profit margin | D37: =D19/D17 -> 0.4413113 | E37: =E19/E17 -> 0.4620635 | F37: =F19/F17 -> 0.46905164
C38: R&D % of sales | D38: =-(D20/D17) -> 0.078048971 | E38: =-(E20/E17) -> 0.080222998 | F38: =-(F20/F17) -> 0.083020754
C39: SG&A % of sales | D39: =-(D21/D17) -> 0.065048202 | E39: =-(E21/E17) -> 0.066738272 | F39: =-(F21/F17) -> 0.066322889
C40: Tax rate | D40: =-(D27/D26) -> 0.14719174 | E40: =-(E27/E26) -> 0.24091185 | F40: =-(F27/F26) -> 0.15610002
C42: BALANCE SHEET
C43: =C14 -> Fiscal year | E43: 2024A | F43: 2025A
C44: =C15 -> Fiscal year end date | E44: =E15 -> 45596 | F44: =F15 -> 45947
C45: Cash & equivalents, ST and LT marketable securities | E45: =29943+35228+91479 -> 156650 | F45: =35934+18763+77723 -> 132420
C46: Accounts receivable | E46: 33410 | F46: 39777
C47: Inventories | E47: 7286 | F47: 5718
...

Sheet FSM Forecasting_Empty
C2: ="Financial Statement Model for "&D5 -> Financial Statement Model for Apple
C3: $ in thousands except per share
C5: Company name | D5: Apple
C6: Ticker | D6: AAPL
C7: Circ break 1=off, 0=on | D7: 1
C8: Latest closing share price | D8: 296.42
C9: Latest closing share price date | D9: 46189
C10: Latest fiscal year end date | D10: 45927
C11: Shares outstanding (millions) | D11: 14776.353
C13: INCOME STATEMENT
C14: Fiscal year | D14: =E14-1 -> 2023 | E14: =F14-1 -> 2024 | F14: =YEAR(D10) -> 2025 | G14: =F14+1 -> 2026 | H14: =G14+1 -> 2027 | I14: =H14+1 -> 2028 | J14: =I14+1 -> 2029 | K14: =J14+1 -> 2030
C15: Fiscal year end date | D15: =EOMONTH(E15,-12) -> 45199 | E15: =EOMONTH(F15,-12) -> 45565 | F15: =D10 -> 45927 | G15: =EOMONTH(F15,12) -> 46295 | H15: =EOMONTH(G15,12) -> 46660 | I15: =EOMONTH(H15,12) -> 47026 | J15: =EOMONTH(I15,12) -> 47391 | K15: =EOMONTH(J15,12) -> 47756 | M15: WSP Comments
C17: Revenue | D17: 383285 | E17: 391035 | F17: 416161 | G17: =F17*(1+G36) -> 436969.05 | H17: =G17*(1+H36) -> 458817.5 | I17: =H17*(1+I36) -> 481758.38 | J17: =I17*(1+J36) -> 505846.3 | K17: =J17*(1+K36) -> 531138.61 | M17: Previous year's revenues x (1+revenue growth rate)
C18: Cost of sales (enter as -) | D18: -214137 | E18: -210352 | F18: -220960 | G18: =G19-G17 -> -232008 | H18: =H19-H17 -> -243608.4 | I18: =I19-I17 -> -255788.82 | J18: =J19-J17 -> -268578.26 | K18: =K19-K17 -> -282007.17 | M18: Plug = Revenue - Gross Profit
C19: Gross Profit | D19: =SUM(D17:D18) -> 169148 | E19: =SUM(E17:E18) -> 180683 | F19: =SUM(F17:F18) -> 195201 | G19: =G17*G37 -> 204961.05 | H19: =H17*H37 -> 215209.1 | I19: =I17*I37 -> 225969.56 | J19: =J17*J37 -> 237268.04 | K19: =K17*K37 -> 249131.44 | M19: Revenue x Gross Profit Margin forecast
C20: Research & development (enter as -) | D20: -29915 | E20: -31370 | F20: -34550 | G20: =-G38*G17 -> -36277.5 | H20: =-H38*H17 -> -38091.375 | I20: =-I38*I17 -> -39995.944 | J20: =-J38*J17 -> -41995.741 | K20: =-K38*K17 -> -44095.528 | M20: Revenue x R&D % of sales forecast
C21: Selling, general & administrative (enter as -) | D21: -24932 | E21: -26097 | F21: -27601 | G21: =-G17*G39 -> -28981.05 | H21: =-H17*H39 -> -30430.103 | I21: =-I17*I39 -> -31951.608 | J21: =-J17*J39 -> -33549.188 | K21: =-K17*K39 -> -35226.647 | M21: Revenue x SG&A % of sales forecast
C22: Operating profit (EBIT) | D22: =D19+D20+D21 -> 114301 | E22: =E19+E20+E21 -> 123216 | F22: =F19+F20+F21 -> 133050 | G22: =G19+G20+G21 -> 139702.5 | H22: =H19+H20+H21 -> 146687.63 | I22: =I19+I20+I21 -> 154022.01 | J22: =J19+J20+J21 -> 161723.11 | K22: =K19+K20+K21 -> 169809.26 | M22: Gross Profit - R&D - SG&A
C23: Interest income | D23: 0 | E23: 0 | F23: 0 | G23: =G156 -> 5112.0223 | H23: =H156 -> 6126.2494 | I23: =I156 -> 7340.2595 | J23: =J156 -> 8845.3404 | K23: =K156 -> 10663.488 | M23: Reference from interest on cash schedule
C24: Interest expense (enter as -) | D24: 0 | E24: 0 | F24: 0 | G24: =-G142 -> -3002.8831 | H24: =-H142 -> -3087.123 | I24: =-I142 -> -3087.123 | J24: =-J142 -> -3087.123 | K24: =-K142 -> -3087.123 | M24: Reference from interest expense schedule
C25: Other expense, net (enter as -) | D25: -565 | E25: 269 | F25: -321 | G25: =F25 -> -321 | H25: =G25 -> -321 | I25: =H25 -> -321 | J25: =I25 -> -321 | K25: =J25 -> -321 | M25: Straight-line
C26: Pretax profit | D26: =SUM(D22:D25) -> 113736 | E26: =SUM(E22:E25) -> 123485 | F26: =SUM(F22:F25) -> 132729 | G26: =SUM(G22:G25) -> 141490.64 | H26: =SUM(H22:H25) -> 149405.75 | I26: =SUM(I22:I25) -> 157954.14 | J26: =SUM(J22:J25) -> 167160.32 | K26: =SUM(K22:K25) -> 177064.63 | M26: EBIT + interest income less interest expense less other expense
C27: Taxes (enter expense as -) | D27: -16741 | E27: -29749 | F27: -20719 | G27: =-G40*G26 -> -22086.692 | H27: =-H40*H26 -> -23322.241 | I27: =-I40*I26 -> -24656.645 | J27: =-J40*J26 -> -26093.73 | K27: =-K40*K26 -> -27639.792 | M27: Pre-tax Profit x Tax Rate forecast
C28: Net income | D28: =SUM(D26:D27) -> 96995 | E28: =SUM(E26:E27) -> 93736 | F28: =SUM(F26:F27) -> 112010 | G28: =SUM(G26:G27) -> 119403.95 | H28: =SUM(H26:H27) -> 126083.51 | I28: =SUM(I26:I27) -> 133297.5 | J28: =SUM(J26:J27) -> 141066.59 | K28: =SUM(K26:K27) -> 149424.83 | M28: Pre-tax Profit less taxes
C30: Depreciation & amortization | D30: 11519 | E30: 11445 | F30: 11698 | G30: =G106 -> 12549.915 | H30: =H106 -> 13457.776 | I30: =I106 -> 14425.049 | J30: =J106 -> 15455.405 | K30: =K106 -> 16552.734 | M30: Reference from D&A schedule
C31: EBITDA | D31: =D22+D30 -> 125820 | E31: =E22+E30 -> 134661 | F31: =F22+F30 -> 144748 | G31: =G22+G30 -> 152252.42 | H31: =H22+H30 -> 160145.4 | I31: =I22+I30 -> 168447.06 | J31: =J22+J30 -> 177178.51 | K31: =K22+K30 -> 186362 | M31: EBIT + D&A
C32: Stock based compensation | D32: 10833 | E32: 11688 | F32: 12863 | G32: =F32*(1+G36) -> 13506.15 | H32: =G32*(1+H36) -> 14181.458 | I32: =H32*(1+I36) -> 14890.53 | J32: =I32*(1+J36) -> 15635.057 | K32: =J32*(1+K36) -> 16416.81 | M32: WSP assumption: grow SBC in-line with revenue growth
C33: Adjusted EBITDA | D33: =SUM(D31:D32) -> 136653 | E33: =SUM(E31:E32) -> 146349 | F33: =SUM(F31:F32) -> 157611 | G33: =SUM(G31:G32) -> 165758.57 | H33: =SUM(H31:H32) -> 174326.86 | I33: =SUM(I31:I32) -> 183337.59 | J33: =SUM(J31:J32) -> 192813.57 | K33: =SUM(K31:K32) -> 202778.81 | M33: EBITDA + Stock-based compensation
C35: Growth rates & margins
C36: Revenue growth | E36: =E17/D17-1 -> 0.020219941 | F36: =F17/E17-1 -> 0.064255118 | G36: 0.05 | H36: 0.05 | I36: 0.05 | J36: =I36 -> 0.05 | K36: =J36 -> 0.05 | M36: JP Morgan estimates through 2021; straight-line growth rate thereafter
C37: Gross profit margin | D37: =D19/D17 -> 0.4413113 | E37: =E19/E17 -> 0.4620635 | F37: =F19/F17 -> 0.46905164 | G37: =F37 -> 0.46905164 | H37: =G37 -> 0.46905164 | I37: =H37 -> 0.46905164 | J37: =I37 -> 0.46905164 | K37: =J37 -> 0.46905164 | M37: JP Morgan estimates through 2021; straight-line margin thereafter
C38: R&D % of sales | D38: =-D20/D17 -> 0.078048971 | E38: =-E20/E17 -> 0.080222998 | F38: =-F20/F17 -> 0.083020754 | G38: =F38 -> 0.083020754 | H38: =G38 -> 0.083020754 | I38: =H38 -> 0.083020754 | J38: =I38 -> 0.083020754 | K38: =J38 -> 0.083020754 | M38: JP Morgan estimates through 2021: straight-line margin thereafter
C39: SG&A % of sales | D39: =-D21/D17 -> 0.065048202 | E39: =-E21/E17 -> 0.066738272 | F39: =-F21/F17 -> 0.066322889 | G39: =F39 -> 0.066322889 | H39: =G39 -> 0.066322889 | I39: =H39 -> 0.066322889 | J39: =I39 -> 0.066322889 | K39: =J39 -> 0.066322889 | M39: JP Morgan estimates through 2021: straight-line margin thereafter
C40: Tax rate | D40: =-(D27/D26) -> 0.14719174 | E40: =-(E27/E26) -> 0.24091185 | F40: =-(F27/F26) -> 0.15610002 | G40: =F40 -> 0.15610002 | H40: =G40 -> 0.15610002 | I40: =H40 -> 0.15610002 | J40: =I40 -> 0.15610002 | K40: =J40 -> 0.15610002 | M40: JP Morgan estimates through 2021: straight-line margin thereafter
C42: BALANCE SHEET
C43: =C14 -> Fiscal year | E43: =E14 -> 2024 | F43: =F14 -> 2025 | G43: =G14 -> 2026 | H43: =H14 -> 2027 | I43: =I14 -> 2028 | J43: =J14 -> 2029 | K43: =K14 -> 2030
C44: =C15 -> Fiscal year end date | E44: =E15 -> 45565 | F44: =F15 -> 45927 | G44: =G15 -> 46295 | H44: =H15 -> 46660 | I44: =I15 -> 47026 | J44: =J15 -> 47391 | K44: =K15 -> 47756
C45: Cash & equivalents, ST and LT marketable securities | E45: =29943+35228+91479 -> 156650 | F45: =35934+18763+77723 -> 132420 | G45: =G90+F45 -> 159695.56 | H45: =H90+G45 -> 190375.83 | I45: =I90+H45 -> 229067.56 | J45: =J90+I45 -> 276380.46 | K45: =K90+J45 -> 332961.71 | M45: Reference from 'net change in cash' line on the cash flow statement
C46: Accounts receivable | E46: 33410 | F46: 39777 | G46: =F46*(1+G36) -> 41765.85 | H46: =G46*(1+H36) -> 43854.143 | I46: =H46*(1+I36) -> 46046.85 | J46: =I46*(1+J36) -> 48349.192 | K46: =J46*(1+K36) -> 50766.652 | M46: Grow in-line with revenue growth
C47: Inventories | E47: 7286 | F47: 5718 | G47: =F47*G18/F18 -> 6003.9 | H47: =G47*H18/G18 -> 6304.095 | I47: =H47*I18/H18 -> 6619.2998 | J47: =I47*J18/I18 -> 6950.2647 | K47: =J47*K18/J18 -> 7297.778 | M47: Grow in-line with cost of sales growth
...

Sheet FSM Forecasting_ProgressCheck1
C2: ="Financial Statement Model for "&D5 -> Financial Statement Model for Apple
C3: $ in thousands except per share
C5: Company name | D5: Apple
C6: Ticker | D6: AAPL
C7: Circ break 1=off, 0=on | D7: 1
C8: Latest closing share price | D8: 171.25
C9: Latest closing share price date | D9: 43500
C10: Latest fiscal year end date | D10: 43372
C11: Shares outstanding (millions) | D11: 4745.398
C13: INCOME STATEMENT
C14: Fiscal year | D14: =E14-1 -> 2016 | E14: =F14-1 -> 2017 | F14: =YEAR(D10) -> 2018 | G14: =F14+1 -> 2019 | H14: =G14+1 -> 2020 | I14: =H14+1 -> 2021 | J14: =I14+1 -> 2022 | K14: =J14+1 -> 2023
C15: Fiscal year end date | D15: =EOMONTH(E15,-12) -> 42643 | E15: =EOMONTH(F15,-12) -> 43008 | F15: =D10 -> 43372 | G15: =EOMONTH(F15,12) -> 43738 | H15: =EOMONTH(G15,12) -> 44104 | I15: =EOMONTH(H15,12) -> 44469 | J15: =EOMONTH(I15,12) -> 44834 | K15: =EOMONTH(J15,12) -> 45199 | M15: WSP Comments
C17: Revenue | D17: 215639 | E17: 229234 | F17: 265595 | G17: =F17*(1+G36) -> 254971.2 | H17: =G17*(1+H36) -> 270269.47 | I17: =H17*(1+I36) -> 288918.07 | J17: =I17*(1+J36) -> 308853.41 | K17: =J17*(1+K36) -> 330164.3 | M17: Previous year's revenues x (1+revenue growth rate)
C18: Cost of sales (enter as -) | D18: -131376 | E18: -141048 | F18: -163756 | G18: =G19-G17 -> -158592.09 | H18: =H19-H17 -> -167296.8 | I18: =I19-I17 -> -178551.36 | J18: =J19-J17 -> -190871.41 | K18: =K19-K17 -> -204041.54 | M18: Plug = Revenue - Gross Profit
C19: Gross Profit | D19: =SUM(D17:D18) -> 84263 | E19: =SUM(E17:E18) -> 88186 | F19: =SUM(F17:F18) -> 101839 | G19: =G17*G37 -> 96379.114 | H19: =H17*H37 -> 102972.67 | I19: =I17*I37 -> 110366.7 | J19: =J17*J37 -> 117982 | K19: =K17*K37 -> 126122.76 | M19: Revenue x Gross Profit Margin forecast
C20: Research & development (enter as -) | D20: -10045 | E20: -11581 | F20: -14236 | G20: =-G38*G17 -> -15808.214 | H20: =-H38*H17 -> -17026.977 | I20: =-I38*I17 -> -18201.838 | J20: =-J38*J17 -> -19457.765 | K20: =-K38*K17 -> -20800.351 | M20: Revenue x R&D % of sales forecast
C21: Selling, general & administrative (enter as -) | D21: -14194 | E21: -15261 | F21: -16705 | G21: =-G17*G39 -> -18867.869 | H21: =-H17*H39 -> -18648.594 | I21: =-I17*I39 -> -19935.347 | J21: =-J17*J39 -> -21310.885 | K21: =-K17*K39 -> -22781.337 | M21: Revenue x SG&A % of sales forecast
C22: Operating profit (EBIT) | D22: =D19+D20+D21 -> 60024 | E22: =E19+E20+E21 -> 61344 | F22: =F19+F20+F21 -> 70898 | G22: =G19+G20+G21 -> 61703.03 | H22: =H19+H20+H21 -> 67297.099 | I22: =I19+I20+I21 -> 72229.516 | J22: =J19+J20+J21 -> 77213.353 | K22: =K19+K20+K21 -> 82541.074 | M22: Gross Profit - R&D - SG&A
C23: Interest income | D23: 3999 | E23: 5201 | F23: 5686 | M23: Reference from interest on cash schedule
C24: Interest expense (enter as -) | D24: -1456 | E24: -2323 | F24: -3240 | M24: Reference from interest expense schedule
C25: Other expense, net (enter as -) | D25: -1195 | E25: -133 | F25: -441 | G25: =F25 -> -441 | H25: =G25 -> -441 | I25: =H25 -> -441 | J25: =I25 -> -441 | K25: =J25 -> -441 | M25: Straight-line
C26: Pretax profit | D26: =SUM(D22:D25) -> 61372 | E26: =SUM(E22:E25) -> 64089 | F26: =SUM(F22:F25) -> 72903 | G26: =SUM(G22:G25) -> 61262.03 | H26: =SUM(H22:H25) -> 66856.099 | I26: =SUM(I22:I25) -> 71788.516 | J26: =SUM(J22:J25) -> 76772.353 | K26: =SUM(K22:K25) -> 82100.074 | M26: EBIT + interest income less interest expense less other expense
C27: Taxes (enter expense as -) | D27: -15685 | E27: -15738 | F27: -13372 | G27: =-G40*G26 -> -10230.759 | H27: =-H40*H26 -> -11365.537 | I27: =-I40*I26 -> -12132.259 | J27: =-J40*J26 -> -12974.528 | K27: =-K40*K26 -> -13874.913 | M27: Pre-tax Profit x Tax Rate forecast
C28: Net income | D28: =SUM(D26:D27) -> 45687 | E28: =SUM(E26:E27) -> 48351 | F28: =SUM(F26:F27) -> 59531 | G28: =SUM(G26:G27) -> 51031.271 | H28: =SUM(H26:H27) -> 55490.562 | I28: =SUM(I26:I27) -> 59656.257 | J28: =SUM(J26:J27) -> 63797.825 | K28: =SUM(K26:K27) -> 68225.162 | M28: Pre-tax Profit less taxes
C30: Depreciation & amortization | D30: 10505 | E30: 10157 | F30: 10903 | M30: Reference from D&A schedule
C31: EBITDA | D31: =D22+D30 -> 70529 | E31: =E22+E30 -> 71501 | F31: =F22+F30 -> 81801 | G31: =G22+G30 -> 61703.03 | H31: =H22+H30 -> 67297.099 | I31: =I22+I30 -> 72229.516 | J31: =J22+J30 -> 77213.353 | K31: =K22+K30 -> 82541.074 | M31: EBIT + D&A
C32: Stock based compensation | D32: 4210 | E32: 4840 | F32: 5340 | G32: =F32*(1+G36) -> 5126.4 | H32: =G32*(1+H36) -> 5433.984 | I32: =H32*(1+I36) -> 5808.9289 | J32: =I32*(1+J36) -> 6209.745 | K32: =J32*(1+K36) -> 6638.2174 | M32: WSP assumption: grow SBC in-line with revenue growth
C33: Adjusted EBITDA | D33: =SUM(D31:D32) -> 74739 | E33: =SUM(E31:E32) -> 76341 | F33: =SUM(F31:F32) -> 87141 | G33: =SUM(G31:G32) -> 66829.43 | H33: =SUM(H31:H32) -> 72731.083 | I33: =SUM(I31:I32) -> 78038.445 | J33: =SUM(J31:J32) -> 83423.098 | K33: =SUM(K31:K32) -> 89179.292 | M33: EBITDA + Stock-based compensation
C35: Growth rates & margins
C36: Revenue growth | E36: =E17/D17-1 -> 0.063045182 | F36: =F17/E17-1 -> 0.15861958 | G36: -0.04 | H36: 0.06 | I36: 0.069 | J36: =I36 -> 0.069 | K36: =J36 -> 0.069 | M36: JP Morgan estimates through 2021; straight-line growth rate thereafter
C37: Gross profit margin | D37: =D19/D17 -> 0.39075956 | E37: =E19/E17 -> 0.3846986 | F37: =F19/F17 -> 0.38343719 | G37: 0.378 | H37: 0.381 | I37: 0.382 | J37: =I37 -> 0.382 | K37: =J37 -> 0.382 | M37: JP Morgan estimates through 2021; straight-line margin thereafter
C38: R&D % of sales | D38: =-D20/D17 -> 0.046582483 | E38: =-E20/E17 -> 0.050520429 | F38: =-F20/F17 -> 0.053600407 | G38: 0.062 | H38: 0.063 | I38: 0.063 | J38: =I38 -> 0.063 | K38: =J38 -> 0.063 | M38: JP Morgan estimates through 2021: straight-line margin thereafter
C39: SG&A % of sales | D39: =-D21/D17 -> 0.065822973 | E39: =-E21/E17 -> 0.066573894 | F39: =-F21/F17 -> 0.062896515 | G39: 0.074 | H39: 0.069 | I39: 0.069 | J39: =I39 -> 0.069 | K39: =J39 -> 0.069 | M39: JP Morgan estimates through 2021: straight-line margin thereafter
C40: Tax rate | D40: =-(D27/D26) -> 0.25557257 | E40: =-(E27/E26) -> 0.24556476 | F40: =-(F27/F26) -> 0.18342181 | G40: 0.167 | H40: 0.17 | I40: 0.169 | J40: =I40 -> 0.169 | K40: =J40 -> 0.169 | M40: JP Morgan estimates through 2021: straight-line margin thereafter
C42: BALANCE SHEET
C43: =C14 -> Fiscal year | E43: =E14 -> 2017 | F43: =F14 -> 2018 | G43: =G14 -> 2019 | H43: =H14 -> 2020 | I43: =I14 -> 2021 | J43: =J14 -> 2022 | K43: =K14 -> 2023
C44: =C15 -> Fiscal year end date | E44: =E15 -> 43008 | F44: =F15 -> 43372 | G44: =G15 -> 43738 | H44: =H15 -> 44104 | I44: =I15 -> 44469 | J44: =J15 -> 44834 | K44: =K15 -> 45199
C45: Cash & equivalents, ST and LT marketable securities | E45: =20289+53892+194714 -> 268895 | F45: =25913+40388+170799 -> 237100 | G45: =G90+F45 -> 290535.04 | H45: =H90+G45 -> 355782.51 | I45: =I90+H45 -> 426721.43 | J45: =J90+I45 -> 502672.04 | K45: =K90+J45 -> 583888.53 | M45: Reference from 'net change in cash' line on the cash flow statement
C46: Accounts receivable | E46: 17874 | F46: 23186 | G46: =F46*(1+G36) -> 22258.56 | H46: =G46*(1+H36) -> 23594.074 | I46: =H46*(1+I36) -> 25222.065 | J46: =I46*(1+J36) -> 26962.387 | K46: =J46*(1+K36) -> 28822.792 | M46: Grow in-line with revenue growth
C47: Inventories | E47: 4855 | F47: 3956 | G47: =F47*G18/F18 -> 3831.2507 | H47: =G47*H18/G18 -> 4041.5383 | I47: =H47*I18/H18 -> 4313.4248 | J47: =I47*J18/I18 -> 4611.0512 | K47: =J47*K18/J18 -> 4929.2137 | M47: Grow in-line with cost of sales growth
...

Sheet FSM Forecasting_ProgressCheck2
C2: ="Financial Statement Model for "&D5 -> Financial Statement Model for Apple
C3: $ in thousands except per share
C5: Company name | D5: Apple
C6: Ticker | D6: AAPL
C7: Circ break 1=off, 0=on | D7: 1
C8: Latest closing share price | D8: 171.25
C9: Latest closing share price date | D9: 43500
C10: Latest fiscal year end date | D10: 43372
C11: Shares outstanding (millions) | D11: 4745.398
C13: INCOME STATEMENT
C14: Fiscal year | D14: =E14-1 -> 2016 | E14: =F14-1 -> 2017 | F14: =YEAR(D10) -> 2018 | G14: =F14+1 -> 2019 | H14: =G14+1 -> 2020 | I14: =H14+1 -> 2021 | J14: =I14+1 -> 2022 | K14: =J14+1 -> 2023
C15: Fiscal year end date | D15: =EOMONTH(E15,-12) -> 42643 | E15: =EOMONTH(F15,-12) -> 43008 | F15: =D10 -> 43372 | G15: =EOMONTH(F15,12) -> 43738 | H15: =EOMONTH(G15,12) -> 44104 | I15: =EOMONTH(H15,12) -> 44469 | J15: =EOMONTH(I15,12) -> 44834 | K15: =EOMONTH(J15,12) -> 45199 | M15: WSP Comments
C17: Revenue | D17: 215639 | E17: 229234 | F17: 265595 | G17: =F17*(1+G36) -> 254971.2 | H17: =G17*(1+H36) -> 270269.47 | I17: =H17*(1+I36) -> 288918.07 | J17: =I17*(1+J36) -> 308853.41 | K17: =J17*(1+K36) -> 330164.3 | M17: Previous year's revenues x (1+revenue growth rate)
C18: Cost of sales (enter as -) | D18: -131376 | E18: -141048 | F18: -163756 | G18: =G19-G17 -> -158592.09 | H18: =H19-H17 -> -167296.8 | I18: =I19-I17 -> -178551.36 | J18: =J19-J17 -> -190871.41 | K18: =K19-K17 -> -204041.54 | M18: Plug = Revenue - Gross Profit
C19: Gross Profit | D19: =SUM(D17:D18) -> 84263 | E19: =SUM(E17:E18) -> 88186 | F19: =SUM(F17:F18) -> 101839 | G19: =G37*G17 -> 96379.114 | H19: =H37*H17 -> 102972.67 | I19: =I37*I17 -> 110366.7 | J19: =J37*J17 -> 117982 | K19: =K37*K17 -> 126122.76 | M19: Revenue x Gross Profit Margin forecast
C20: Research & development (enter as -) | D20: -10045 | E20: -11581 | F20: -14236 | G20: =-(G38*G17) -> -15808.214 | H20: =-(H38*H17) -> -17026.977 | I20: =-(I38*I17) -> -18201.838 | J20: =-(J38*J17) -> -19457.765 | K20: =-(K38*K17) -> -20800.351 | M20: Revenue x R&D % of sales forecast
C21: Selling, general & administrative (enter as -) | D21: -14194 | E21: -15261 | F21: -16705 | G21: =-(G39*G17) -> -18867.869 | H21: =-(H39*H17) -> -18648.594 | I21: =-(I39*I17) -> -19935.347 | J21: =-(J39*J17) -> -21310.885 | K21: =-(K39*K17) -> -22781.337 | M21: Revenue x SG&A % of sales forecast
C22: Operating profit (EBIT) | D22: =D19+D20+D21 -> 60024 | E22: =E19+E20+E21 -> 61344 | F22: =F19+F20+F21 -> 70898 | G22: =G19+G20+G21 -> 61703.03 | H22: =H19+H20+H21 -> 67297.099 | I22: =I19+I20+I21 -> 72229.516 | J22: =J19+J20+J21 -> 77213.353 | K22: =K19+K20+K21 -> 82541.074 | M22: Gross Profit - R&D - SG&A
C23: Interest income | D23: 3999 | E23: 5201 | F23: 5686 | M23: Reference from interest on cash schedule
C24: Interest expense (enter as -) | D24: -1456 | E24: -2323 | F24: -3240 | M24: Reference from interest expense schedule
C25: Other expense, net (enter as -) | D25: -1195 | E25: -133 | F25: -441 | G25: =F25 -> -441 | H25: =G25 -> -441 | I25: =H25 -> -441 | J25: =I25 -> -441 | K25: =J25 -> -441 | M25: Straight-line
C26: Pretax profit | D26: =SUM(D22:D25) -> 61372 | E26: =SUM(E22:E25) -> 64089 | F26: =SUM(F22:F25) -> 72903 | G26: =SUM(G22:G25) -> 61262.03 | H26: =SUM(H22:H25) -> 66856.099 | I26: =SUM(I22:I25) -> 71788.516 | J26: =SUM(J22:J25) -> 76772.353 | K26: =SUM(K22:K25) -> 82100.074 | M26: EBIT + interest income less interest expense less other expense
C27: Taxes (enter expense as -) | D27: -15685 | E27: -15738 | F27: -13372 | G27: =-G40*G26 -> -10230.759 | H27: =-H40*H26 -> -11365.537 | I27: =-I40*I26 -> -12132.259 | J27: =-J40*J26 -> -12974.528 | K27: =-K40*K26 -> -13874.913 | M27: Pre-tax Profit x Tax Rate forecast
C28: Net income | D28: =SUM(D26:D27) -> 45687 | E28: =SUM(E26:E27) -> 48351 | F28: =SUM(F26:F27) -> 59531 | G28: =SUM(G26:G27) -> 51031.271 | H28: =SUM(H26:H27) -> 55490.562 | I28: =SUM(I26:I27) -> 59656.257 | J28: =SUM(J26:J27) -> 63797.825 | K28: =SUM(K26:K27) -> 68225.162 | M28: Pre-tax Profit less taxes
C30: Depreciation & amortization | D30: 10505 | E30: 10157 | F30: 10903 | G30: =G106 -> 11085.02 | H30: =H106 -> 11711.891 | I30: =I106 -> 12226.381 | J30: =J106 -> 13365.451 | K30: =K106 -> 14603.503 | M30: Reference from D&A schedule
C31: EBITDA | D31: =D22+D30 -> 70529 | E31: =E22+E30 -> 71501 | F31: =F22+F30 -> 81801 | G31: =G22+G30 -> 72788.051 | H31: =H22+H30 -> 79008.989 | I31: =I22+I30 -> 84455.897 | J31: =J22+J30 -> 90578.804 | K31: =K22+K30 -> 97144.578 | M31: EBIT + D&A
C32: Stock based compensation | D32: 4210 | E32: 4840 | F32: 5340 | G32: =F32*(1+G36) -> 5126.4 | H32: =G32*(1+H36) -> 5433.984 | I32: =H32*(1+I36) -> 5808.9289 | J32: =I32*(1+J36) -> 6209.745 | K32: =J32*(1+K36) -> 6638.2174 | M32: WSP assumption: grow SBC in-line with revenue growth
C33: Adjusted EBITDA | D33: =SUM(D31:D32) -> 74739 | E33: =SUM(E31:E32) -> 76341 | F33: =SUM(F31:F32) -> 87141 | G33: =SUM(G31:G32) -> 77914.451 | H33: =SUM(H31:H32) -> 84442.973 | I33: =SUM(I31:I32) -> 90264.826 | J33: =SUM(J31:J32) -> 96788.549 | K33: =SUM(K31:K32) -> 103782.8 | M33: EBITDA + Stock-based compensation
C35: Growth rates & margins
C36: Revenue growth | E36: =E17/D17-1 -> 0.063045182 | F36: =F17/E17-1 -> 0.15861958 | G36: -0.04 | H36: 0.06 | I36: 0.069 | J36: =I36 -> 0.069 | K36: =J36 -> 0.069 | M36: JP Morgan estimates through 2021; straight-line growth rate thereafter
C37: Gross profit margin | D37: =D19/D17 -> 0.39075956 | E37: =E19/E17 -> 0.3846986 | F37: =F19/F17 -> 0.38343719 | G37: 0.378 | H37: 0.381 | I37: 0.382 | J37: =I37 -> 0.382 | K37: =J37 -> 0.382 | M37: JP Morgan estimates through 2021; straight-line margin thereafter
C38: R&D % of sales | D38: =-D20/D17 -> 0.046582483 | E38: =-E20/E17 -> 0.050520429 | F38: =-F20/F17 -> 0.053600407 | G38: 0.062 | H38: 0.063 | I38: 0.063 | J38: =I38 -> 0.063 | K38: =J38 -> 0.063 | M38: JP Morgan estimates through 2021: straight-line margin thereafter
C39: SG&A % of sales | D39: =-D21/D17 -> 0.065822973 | E39: =-E21/E17 -> 0.066573894 | F39: =-F21/F17 -> 0.062896515 | G39: 0.074 | H39: 0.069 | I39: 0.069 | J39: =I39 -> 0.069 | K39: =J39 -> 0.069 | M39: JP Morgan estimates through 2021: straight-line margin thereafter
C40: Tax rate | D40: =-(D27/D26) -> 0.25557257 | E40: =-(E27/E26) -> 0.24556476 | F40: =-(F27/F26) -> 0.18342181 | G40: 0.167 | H40: 0.17 | I40: 0.169 | J40: =I40 -> 0.169 | K40: =J40 -> 0.169 | M40: JP Morgan estimates through 2021: straight-line margin thereafter
C42: BALANCE SHEET
C43: =C14 -> Fiscal year | E43: =E14 -> 2017 | F43: =F14 -> 2018 | G43: =G14 -> 2019 | H43: =H14 -> 2020 | I43: =I14 -> 2021 | J43: =J14 -> 2022 | K43: =K14 -> 2023
C44: =C15 -> Fiscal year end date | E44: =E15 -> 43008 | F44: =F15 -> 43372 | G44: =G15 -> 43738 | H44: =H15 -> 44104 | I44: =I15 -> 44469 | J44: =J15 -> 44834 | K44: =K15 -> 45199
C45: Cash & equivalents, ST and LT marketable securities | E45: =20289+53892+194714 -> 268895 | F45: =25913+40388+170799 -> 237100 | G45: =F45+G90 -> 200896.5 | H45: =G45+H90 -> 174501.15 | I45: =H45+I90 -> 153748.09 | J45: =I45+J90 -> 137964.01 | K45: =J45+K90 -> 127420.53 | M45: Reference from 'net change in cash' line on the cash flow statement
C46: Accounts receivable | E46: 17874 | F46: 23186 | G46: =F46*(1+G36) -> 22258.56 | H46: =G46*(1+H36) -> 23594.074 | I46: =H46*(1+I36) -> 25222.065 | J46: =I46*(1+J36) -> 26962.387 | K46: =J46*(1+K36) -> 28822.792 | M46: Grow in-line with revenue growth
C47: Inventories | E47: 4855 | F47: 3956 | G47: =F47*(G18/F18) -> 3831.2507 | H47: =G47*(H18/G18) -> 4041.5383 | I47: =H47*(I18/H18) -> 4313.4248 | J47: =I47*(J18/I18) -> 4611.0512 | K47: =J47*(K18/J18) -> 4929.2137 | M47: Grow in-line with cost of sales growth
...

Sheet FSM Forecasting_Empty II
C2: ="Financial Statement Model for "&D5 -> Financial Statement Model for Apple
C3: $ in thousands except per share
C5: Company name | D5: Apple
C6: Ticker | D6: AAPL
D7: 1
C8: Latest closing share price | D8: 171.25
C9: Latest closing share price date | D9: 43500
C10: Latest fiscal year end date | D10: 43372
C11: Shares outstanding (millions) | D11: 4745.398
C13: INCOME STATEMENT
C14: Fiscal year | D14: =E14-1 -> 2016 | E14: =F14-1 -> 2017 | F14: =YEAR(D10) -> 2018 | G14: =F14+1 -> 2019 | H14: =G14+1 -> 2020 | I14: =H14+1 -> 2021 | J14: =I14+1 -> 2022 | K14: =J14+1 -> 2023
C15: Fiscal year end date | D15: =EOMONTH(E15,-12) -> 42643 | E15: =EOMONTH(F15,-12) -> 43008 | F15: =D10 -> 43372 | G15: =EOMONTH(F15,12) -> 43738 | H15: =EOMONTH(G15,12) -> 44104 | I15: =EOMONTH(H15,12) -> 44469 | J15: =EOMONTH(I15,12) -> 44834 | K15: =EOMONTH(J15,12) -> 45199 | M15: WSP Comments
C17: Revenue | D17: 215639 | E17: 229234 | F17: 265595 | G17: =F17*(1+G36) -> 254971.2 | H17: =G17*(1+H36) -> 270269.47 | I17: =H17*(1+I36) -> 288918.07 | J17: =I17*(1+J36) -> 308853.41 | K17: =J17*(1+K36) -> 330164.3 | M17: Previous year's revenues x (1+revenue growth rate)
C18: Cost of sales (enter as -) | D18: -131376 | E18: -141048 | F18: -163756 | G18: =G19-G17 -> -158592.09 | H18: =H19-H17 -> -167296.8 | I18: =I19-I17 -> -178551.36 | J18: =J19-J17 -> -190871.41 | K18: =K19-K17 -> -204041.54 | M18: Plug = Revenue - Gross Profit
C19: Gross Profit | D19: =SUM(D17:D18) -> 84263 | E19: =SUM(E17:E18) -> 88186 | F19: =SUM(F17:F18) -> 101839 | G19: =G17*G37 -> 96379.114 | H19: =H17*H37 -> 102972.67 | I19: =I17*I37 -> 110366.7 | J19: =J17*J37 -> 117982 | K19: =K17*K37 -> 126122.76 | M19: Revenue x Gross Profit Margin forecast
C20: Research & development (enter as -) | D20: -10045 | E20: -11581 | F20: -14236 | G20: =-G38*G17 -> -15808.214 | H20: =-H38*H17 -> -17026.977 | I20: =-I38*I17 -> -18201.838 | J20: =-J38*J17 -> -19457.765 | K20: =-K38*K17 -> -20800.351 | M20: Revenue x R&D % of sales forecast
C21: Selling, general & administrative (enter as -) | D21: -14194 | E21: -15261 | F21: -16705 | G21: =-G17*G39 -> -18867.869 | H21: =-H17*H39 -> -18648.594 | I21: =-I17*I39 -> -19935.347 | J21: =-J17*J39 -> -21310.885 | K21: =-K17*K39 -> -22781.337 | M21: Revenue x SG&A % of sales forecast
C22: Operating profit (EBIT) | D22: =D19+D20+D21 -> 60024 | E22: =E19+E20+E21 -> 61344 | F22: =F19+F20+F21 -> 70898 | G22: =G19+G20+G21 -> 61703.03 | H22: =H19+H20+H21 -> 67297.099 | I22: =I19+I20+I21 -> 72229.516 | J22: =J19+J20+J21 -> 77213.353 | K22: =K19+K20+K21 -> 82541.074 | M22: Gross Profit - R&D - SG&A
C23: Interest income | D23: 3999 | E23: 5201 | F23: 5686 | G23: =G156 -> 4744.4371 | H23: =H156 -> 4090.2133 | I23: =I156 -> 3592.0871 | J23: =J156 -> 3200.5876 | K23: =K156 -> 2913.2593 | M23: Reference from interest on cash schedule
C24: Interest expense (enter as -) | D24: -1456 | E24: -2323 | F24: -3240 | G24: =-G142 -> -3223.1469 | H24: =-H142 -> -3223.5393 | I24: =-I142 -> -3223.5393 | J24: =-J142 -> -3223.5393 | K24: =-K142 -> -3223.5393 | M24: Reference from interest expense schedule
C25: Other expense, net (enter as -) | D25: -1195 | E25: -133 | F25: -441 | G25: =F25 -> -441 | H25: =G25 -> -441 | I25: =H25 -> -441 | J25: =I25 -> -441 | K25: =J25 -> -441 | M25: Straight-line
C26: Pretax profit | D26: =SUM(D22:D25) -> 61372 | E26: =SUM(E22:E25) -> 64089 | F26: =SUM(F22:F25) -> 72903 | G26: =SUM(G22:G25) -> 62783.321 | H26: =SUM(H22:H25) -> 67722.773 | I26: =SUM(I22:I25) -> 72157.064 | J26: =SUM(J22:J25) -> 76749.401 | K26: =SUM(K22:K25) -> 81789.794 | M26: EBIT + interest income less interest expense less other expense
C27: Taxes (enter expense as -) | D27: -15685 | E27: -15738 | F27: -13372 | G27: =-G40*G26 -> -10484.815 | H27: =-H40*H26 -> -11512.871 | I27: =-I40*I26 -> -12194.544 | J27: =-J40*J26 -> -12970.649 | K27: =-K40*K26 -> -13822.475 | M27: Pre-tax Profit x Tax Rate forecast
C28: Net income | D28: =SUM(D26:D27) -> 45687 | E28: =SUM(E26:E27) -> 48351 | F28: =SUM(F26:F27) -> 59531 | G28: =SUM(G26:G27) -> 52298.506 | H28: =SUM(H26:H27) -> 56209.901 | I28: =SUM(I26:I27) -> 59962.52 | J28: =SUM(J26:J27) -> 63778.753 | K28: =SUM(K26:K27) -> 67967.319 | M28: Pre-tax Profit less taxes
C30: Depreciation & amortization | D30: 10505 | E30: 10157 | F30: 10903 | G30: =G106 -> 11085.02 | H30: =H106 -> 11711.891 | I30: =I106 -> 12226.381 | J30: =J106 -> 13365.451 | K30: =K106 -> 14603.503 | M30: Reference from D&A schedule
C31: EBITDA | D31: =D22+D30 -> 70529 | E31: =E22+E30 -> 71501 | F31: =F22+F30 -> 81801 | G31: =G22+G30 -> 72788.051 | H31: =H22+H30 -> 79008.989 | I31: =I22+I30 -> 84455.897 | J31: =J22+J30 -> 90578.804 | K31: =K22+K30 -> 97144.578 | M31: EBIT + D&A
C32: Stock based compensation | D32: 4210 | E32: 4840 | F32: 5340 | G32: =F32*(1+G36) -> 5126.4 | H32: =G32*(1+H36) -> 5433.984 | I32: =H32*(1+I36) -> 5808.9289 | J32: =I32*(1+J36) -> 6209.745 | K32: =J32*(1+K36) -> 6638.2174 | M32: WSP assumption: grow SBC in-line with revenue growth
C33: Adjusted EBITDA | D33: =SUM(D31:D32) -> 74739 | E33: =SUM(E31:E32) -> 76341 | F33: =SUM(F31:F32) -> 87141 | G33: =SUM(G31:G32) -> 77914.451 | H33: =SUM(H31:H32) -> 84442.973 | I33: =SUM(I31:I32) -> 90264.826 | J33: =SUM(J31:J32) -> 96788.549 | K33: =SUM(K31:K32) -> 103782.8 | M33: EBITDA + Stock-based compensation
C35: Growth rates & margins
C36: Revenue growth | E36: =E17/D17-1 -> 0.063045182 | F36: =F17/E17-1 -> 0.15861958 | G36: -0.04 | H36: 0.06 | I36: 0.069 | J36: =I36 -> 0.069 | K36: =J36 -> 0.069 | M36: JP Morgan estimates through 2021; straight-line growth rate thereafter
C37: Gross profit margin | D37: =D19/D17 -> 0.39075956 | E37: =E19/E17 -> 0.3846986 | F37: =F19/F17 -> 0.38343719 | G37: 0.378 | H37: 0.381 | I37: 0.382 | J37: =I37 -> 0.382 | K37: =J37 -> 0.382 | M37: JP Morgan estimates through 2021; straight-line margin thereafter
C38: R&D % of sales | D38: =-D20/D17 -> 0.046582483 | E38: =-E20/E17 -> 0.050520429 | F38: =-F20/F17 -> 0.053600407 | G38: 0.062 | H38: 0.063 | I38: 0.063 | J38: =I38 -> 0.063 | K38: =J38 -> 0.063 | M38: JP Morgan estimates through 2021: straight-line margin thereafter
C39: SG&A % of sales | D39: =-D21/D17 -> 0.065822973 | E39: =-E21/E17 -> 0.066573894 | F39: =-F21/F17 -> 0.062896515 | G39: 0.074 | H39: 0.069 | I39: 0.069 | J39: =I39 -> 0.069 | K39: =J39 -> 0.069 | M39: JP Morgan estimates through 2021: straight-line margin thereafter
C40: Tax rate | D40: =-(D27/D26) -> 0.25557257 | E40: =-(E27/E26) -> 0.24556476 | F40: =-(F27/F26) -> 0.18342181 | G40: 0.167 | H40: 0.17 | I40: 0.169 | J40: =I40 -> 0.169 | K40: =J40 -> 0.169 | M40: JP Morgan estimates through 2021: straight-line margin thereafter
C42: BALANCE SHEET
C43: =C14 -> Fiscal year | E43: =E14 -> 2017 | F43: =F14 -> 2018 | G43: =G14 -> 2019 | H43: =H14 -> 2020 | I43: =I14 -> 2021 | J43: =J14 -> 2022 | K43: =K14 -> 2023
C44: =C15 -> Fiscal year end date | E44: =E15 -> 43008 | F44: =F15 -> 43372 | G44: =G15 -> 43738 | H44: =H15 -> 44104 | I44: =I15 -> 44469 | J44: =J15 -> 44834 | K44: =K15 -> 45199
C45: Cash & equivalents, ST and LT marketable securities | E45: =20289+53892+194714 -> 268895 | F45: =25913+40388+170799 -> 237100 | G45: =G90+F45 -> 202199.73 | H45: =H90+G45 -> 176523.72 | I45: =I90+H45 -> 156076.93 | J45: =J90+I45 -> 140273.78 | K45: =K90+J45 -> 129472.46 | M45: Reference from 'net change in cash' line on the cash flow statement
C46: Accounts receivable | E46: 17874 | F46: 23186 | G46: =F46*(1+G36) -> 22258.56 | H46: =G46*(1+H36) -> 23594.074 | I46: =H46*(1+I36) -> 25222.065 | J46: =I46*(1+J36) -> 26962.387 | K46: =J46*(1+K36) -> 28822.792 | M46: Grow in-line with revenue growth
C47: Inventories | E47: 4855 | F47: 3956 | G47: =F47*G18/F18 -> 3831.2507 | H47: =G47*H18/G18 -> 4041.5383 | I47: =H47*I18/H18 -> 4313.4248 | J47: =I47*J18/I18 -> 4611.0512 | K47: =J47*K18/J18 -> 4929.2137 | M47: Grow in-line with cost of sales growth
...

Sheet FSM Complete
C2: ="Financial Statement Model for "&D5 -> Financial Statement Model for Apple
C3: $ in thousands except per share
C5: Company name | D5: Apple
C6: Ticker | D6: AAPL
C7: Circ break 1=off, 0=on | D7: 1
C8: Latest closing share price | D8: 171.25
C9: Latest closing share price date | D9: 43500
C10: Latest fiscal year end date | D10: 43372
C11: Shares outstanding (millions) | D11: 4745.398
C13: INCOME STATEMENT
C14: Fiscal year | D14: =E14-1 -> 2016 | E14: =F14-1 -> 2017 | F14: =YEAR(D10) -> 2018 | G14: =F14+1 -> 2019 | H14: =G14+1 -> 2020 | I14: =H14+1 -> 2021 | J14: =I14+1 -> 2022 | K14: =J14+1 -> 2023
C15: Fiscal year end date | D15: =EOMONTH(E15,-12) -> 42643 | E15: =EOMONTH(F15,-12) -> 43008 | F15: =D10 -> 43372 | G15: =EOMONTH(F15,12) -> 43738 | H15: =EOMONTH(G15,12) -> 44104 | I15: =EOMONTH(H15,12) -> 44469 | J15: =EOMONTH(I15,12) -> 44834 | K15: =EOMONTH(J15,12) -> 45199 | M15: WSP Comments
C17: Revenue | D17: 215639 | E17: 229234 | F17: 265595 | G17: =F17*(1+G36) -> 254971.2 | H17: =G17*(1+H36) -> 270269.47 | I17: =H17*(1+I36) -> 288918.07 | J17: =I17*(1+J36) -> 308853.41 | K17: =J17*(1+K36) -> 330164.3 | M17: Previous year's revenues x (1+revenue growth rate)
C18: Cost of sales (enter as -) | D18: -131376 | E18: -141048 | F18: -163756 | G18: =G19-G17 -> -158592.09 | H18: =H19-H17 -> -167296.8 | I18: =I19-I17 -> -178551.36 | J18: =J19-J17 -> -190871.41 | K18: =K19-K17 -> -204041.54 | M18: Plug = Revenue - Gross Profit
C19: Gross Profit | D19: =SUM(D17:D18) -> 84263 | E19: =SUM(E17:E18) -> 88186 | F19: =SUM(F17:F18) -> 101839 | G19: =G17*G37 -> 96379.114 | H19: =H17*H37 -> 102972.67 | I19: =I17*I37 -> 110366.7 | J19: =J17*J37 -> 117982 | K19: =K17*K37 -> 126122.76 | M19: Revenue x Gross Profit Margin forecast
C20: Research & development (enter as -) | D20: -10045 | E20: -11581 | F20: -14236 | G20: =-G38*G17 -> -15808.214 | H20: =-H38*H17 -> -17026.977 | I20: =-I38*I17 -> -18201.838 | J20: =-J38*J17 -> -19457.765 | K20: =-K38*K17 -> -20800.351 | M20: Revenue x R&D % of sales forecast
C21: Selling, general & administrative (enter as -) | D21: -14194 | E21: -15261 | F21: -16705 | G21: =-G17*G39 -> -18867.869 | H21: =-H17*H39 -> -18648.594 | I21: =-I17*I39 -> -19935.347 | J21: =-J17*J39 -> -21310.885 | K21: =-K17*K39 -> -22781.337 | M21: Revenue x SG&A % of sales forecast
C22: Operating profit (EBIT) | D22: =D19+D20+D21 -> 60024 | E22: =E19+E20+E21 -> 61344 | F22: =F19+F20+F21 -> 70898 | G22: =G19+G20+G21 -> 61703.03 | H22: =H19+H20+H21 -> 67297.099 | I22: =I19+I20+I21 -> 72229.516 | J22: =J19+J20+J21 -> 77213.353 | K22: =K19+K20+K21 -> 82541.074 | M22: Gross Profit - R&D - SG&A
C23: Interest income | D23: 3999 | E23: 5201 | F23: 5686 | G23: =G156 -> 4744.4371 | H23: =H156 -> 4090.2133 | I23: =I156 -> 3592.0871 | J23: =J156 -> 3200.5876 | K23: =K156 -> 2913.2593 | M23: Reference from interest on cash schedule
C24: Interest expense (enter as -) | D24: -1456 | E24: -2323 | F24: -3240 | G24: =-G142 -> -3223.1469 | H24: =-H142 -> -3223.5393 | I24: =-I142 -> -3223.5393 | J24: =-J142 -> -3223.5393 | K24: =-K142 -> -3223.5393 | M24: Reference from interest expense schedule
C25: Other expense, net (enter as -) | D25: -1195 | E25: -133 | F25: -441 | G25: =F25 -> -441 | H25: =G25 -> -441 | I25: =H25 -> -441 | J25: =I25 -> -441 | K25: =J25 -> -441 | M25: Straight-line
C26: Pretax profit | D26: =SUM(D22:D25) -> 61372 | E26: =SUM(E22:E25) -> 64089 | F26: =SUM(F22:F25) -> 72903 | G26: =SUM(G22:G25) -> 62783.321 | H26: =SUM(H22:H25) -> 67722.773 | I26: =SUM(I22:I25) -> 72157.064 | J26: =SUM(J22:J25) -> 76749.401 | K26: =SUM(K22:K25) -> 81789.794 | M26: EBIT + interest income less interest expense less other expense
C27: Taxes (enter expense as -) | D27: -15685 | E27: -15738 | F27: -13372 | G27: =-G40*G26 -> -10484.815 | H27: =-H40*H26 -> -11512.871 | I27: =-I40*I26 -> -12194.544 | J27: =-J40*J26 -> -12970.649 | K27: =-K40*K26 -> -13822.475 | M27: Pre-tax Profit x Tax Rate forecast
C28: Net income | D28: =SUM(D26:D27) -> 45687 | E28: =SUM(E26:E27) -> 48351 | F28: =SUM(F26:F27) -> 59531 | G28: =SUM(G26:G27) -> 52298.506 | H28: =SUM(H26:H27) -> 56209.901 | I28: =SUM(I26:I27) -> 59962.52 | J28: =SUM(J26:J27) -> 63778.753 | K28: =SUM(K26:K27) -> 67967.319 | M28: Pre-tax Profit less taxes
C30: Depreciation & amortization | D30: 10505 | E30: 10157 | F30: 10903 | G30: =G106 -> 11085.02 | H30: =H106 -> 11711.891 | I30: =I106 -> 12226.381 | J30: =J106 -> 13365.451 | K30: =K106 -> 14603.503 | M30: Reference from D&A schedule
C31: EBITDA | D31: =D22+D30 -> 70529 | E31: =E22+E30 -> 71501 | F31: =F22+F30 -> 81801 | G31: =G22+G30 -> 72788.051 | H31: =H22+H30 -> 79008.989 | I31: =I22+I30 -> 84455.897 | J31: =J22+J30 -> 90578.804 | K31: =K22+K30 -> 97144.578 | M31: EBIT + D&A
C32: Stock based compensation | D32: 4210 | E32: 4840 | F32: 5340 | G32: =F32*(1+G36) -> 5126.4 | H32: =G32*(1+H36) -> 5433.984 | I32: =H32*(1+I36) -> 5808.9289 | J32: =I32*(1+J36) -> 6209.745 | K32: =J32*(1+K36) -> 6638.2174 | M32: WSP assumption: grow SBC in-line with revenue growth
C33: Adjusted EBITDA | D33: =SUM(D31:D32) -> 74739 | E33: =SUM(E31:E32) -> 76341 | F33: =SUM(F31:F32) -> 87141 | G33: =SUM(G31:G32) -> 77914.451 | H33: =SUM(H31:H32) -> 84442.973 | I33: =SUM(I31:I32) -> 90264.826 | J33: =SUM(J31:J32) -> 96788.549 | K33: =SUM(K31:K32) -> 103782.8 | M33: EBITDA + Stock-based compensation
C35: Growth rates & margins
C36: Revenue growth | E36: =E17/D17-1 -> 0.063045182 | F36: =F17/E17-1 -> 0.15861958 | G36: -0.04 | H36: 0.06 | I36: 0.069 | J36: =I36 -> 0.069 | K36: =J36 -> 0.069 | M36: JP Morgan estimates through 2021; straight-line growth rate thereafter
C37: Gross profit margin | D37: =D19/D17 -> 0.39075956 | E37: =E19/E17 -> 0.3846986 | F37: =F19/F17 -> 0.38343719 | G37: 0.378 | H37: 0.381 | I37: 0.382 | J37: =I37 -> 0.382 | K37: =J37 -> 0.382 | M37: JP Morgan estimates through 2021; straight-line margin thereafter
C38: R&D % of sales | D38: =-D20/D17 -> 0.046582483 | E38: =-E20/E17 -> 0.050520429 | F38: =-F20/F17 -> 0.053600407 | G38: 0.062 | H38: 0.063 | I38: 0.063 | J38: =I38 -> 0.063 | K38: =J38 -> 0.063 | M38: JP Morgan estimates through 2021: straight-line margin thereafter
C39: SG&A % of sales | D39: =-D21/D17 -> 0.065822973 | E39: =-E21/E17 -> 0.066573894 | F39: =-F21/F17 -> 0.062896515 | G39: 0.074 | H39: 0.069 | I39: 0.069 | J39: =I39 -> 0.069 | K39: =J39 -> 0.069 | M39: JP Morgan estimates through 2021: straight-line margin thereafter
C40: Tax rate | D40: =-(D27/D26) -> 0.25557257 | E40: =-(E27/E26) -> 0.24556476 | F40: =-(F27/F26) -> 0.18342181 | G40: 0.167 | H40: 0.17 | I40: 0.169 | J40: =I40 -> 0.169 | K40: =J40 -> 0.169 | M40: JP Morgan estimates through 2021: straight-line margin thereafter
C42: BALANCE SHEET
C43: =C14 -> Fiscal year | E43: =E14 -> 2017 | F43: =F14 -> 2018 | G43: =G14 -> 2019 | H43: =H14 -> 2020 | I43: =I14 -> 2021 | J43: =J14 -> 2022 | K43: =K14 -> 2023
C44: =C15 -> Fiscal year end date | E44: =E15 -> 43008 | F44: =F15 -> 43372 | G44: =G15 -> 43738 | H44: =H15 -> 44104 | I44: =I15 -> 44469 | J44: =J15 -> 44834 | K44: =K15 -> 45199
C45: Cash & equivalents, ST and LT marketable securities | E45: =20289+53892+194714 -> 268895 | F45: =25913+40388+170799 -> 237100 | G45: =G90+F45 -> 202199.73 | H45: =H90+G45 -> 176523.72 | I45: =I90+H45 -> 156076.93 | J45: =J90+I45 -> 140273.78 | K45: =K90+J45 -> 129472.46 | M45: Reference from 'net change in cash' line on the cash flow statement
C46: Accounts receivable | E46: 17874 | F46: 23186 | G46: =F46*(1+G36) -> 22258.56 | H46: =G46*(1+H36) -> 23594.074 | I46: =H46*(1+I36) -> 25222.065 | J46: =I46*(1+J36) -> 26962.387 | K46: =J46*(1+K36) -> 28822.792 | M46: Grow in-line with revenue growth
C47: Inventories | E47: 4855 | F47: 3956 | G47: =F47*G18/F18 -> 3831.2507 | H47: =G47*H18/G18 -> 4041.5383 | I47: =H47*I18/H18 -> 4313.4248 | J47: =I47*J18/I18 -> 4611.0512 | K47: =J47*K18/J18 -> 4929.2137 | M47: Grow in-line with cost of sales growth
...

Sheet FSM 2025
C2: ="Financial Statement Model for "&D5 -> Financial Statement Model for Apple
C3: $ in thousands except per share
C5: Company name | D5: Apple
C6: Ticker | D6: AAPL
C7: Circ break 1=off, 0=on | D7: 1
C8: Latest closing share price | D8: 296.42
C9: Latest closing share price date | D9: 46189
C10: Latest fiscal year end date | D10: 45927
C11: Shares outstanding (millions) | D11: 14776.353
C13: INCOME STATEMENT
C14: Fiscal year | D14: =E14-1 -> 2023 | E14: =F14-1 -> 2024 | F14: =YEAR(D10) -> 2025 | G14: =F14+1 -> 2026 | H14: =G14+1 -> 2027 | I14: =H14+1 -> 2028 | J14: =I14+1 -> 2029 | K14: =J14+1 -> 2030
C15: Fiscal year end date | D15: =EOMONTH(E15,-12) -> 45199 | E15: =EOMONTH(F15,-12) -> 45565 | F15: =D10 -> 45927 | G15: =EOMONTH(F15,12) -> 46295 | H15: =EOMONTH(G15,12) -> 46660 | I15: =EOMONTH(H15,12) -> 47026 | J15: =EOMONTH(I15,12) -> 47391 | K15: =EOMONTH(J15,12) -> 47756 | M15: WSP Comments
C17: Revenue | D17: 383285 | E17: 391035 | F17: 416161 | G17: =F17*(1+G36) -> 436969.05 | H17: =G17*(1+H36) -> 458817.5 | I17: =H17*(1+I36) -> 481758.38 | J17: =I17*(1+J36) -> 505846.3 | K17: =J17*(1+K36) -> 531138.61 | M17: Previous year's revenues x (1+revenue growth rate)
C18: Cost of sales (enter as -) | D18: -214137 | E18: -210352 | F18: -220960 | G18: =G19-G17 -> -232008 | H18: =H19-H17 -> -243608.4 | I18: =I19-I17 -> -255788.82 | J18: =J19-J17 -> -268578.26 | K18: =K19-K17 -> -282007.17 | M18: Plug = Revenue - Gross Profit
C19: Gross Profit | D19: =SUM(D17:D18) -> 169148 | E19: =SUM(E17:E18) -> 180683 | F19: =SUM(F17:F18) -> 195201 | G19: =G17*G37 -> 204961.05 | H19: =H17*H37 -> 215209.1 | I19: =I17*I37 -> 225969.56 | J19: =J17*J37 -> 237268.04 | K19: =K17*K37 -> 249131.44 | M19: Revenue x Gross Profit Margin forecast
C20: Research & development (enter as -) | D20: -29915 | E20: -31370 | F20: -34550 | G20: =-G38*G17 -> -36277.5 | H20: =-H38*H17 -> -38091.375 | I20: =-I38*I17 -> -39995.944 | J20: =-J38*J17 -> -41995.741 | K20: =-K38*K17 -> -44095.528 | M20: Revenue x R&D % of sales forecast
C21: Selling, general & administrative (enter as -) | D21: -24932 | E21: -26097 | F21: -27601 | G21: =-G17*G39 -> -28981.05 | H21: =-H17*H39 -> -30430.103 | I21: =-I17*I39 -> -31951.608 | J21: =-J17*J39 -> -33549.188 | K21: =-K17*K39 -> -35226.647 | M21: Revenue x SG&A % of sales forecast
C22: Operating profit (EBIT) | D22: =D19+D20+D21 -> 114301 | E22: =E19+E20+E21 -> 123216 | F22: =F19+F20+F21 -> 133050 | G22: =G19+G20+G21 -> 139702.5 | H22: =H19+H20+H21 -> 146687.63 | I22: =I19+I20+I21 -> 154022.01 | J22: =J19+J20+J21 -> 161723.11 | K22: =K19+K20+K21 -> 169809.26 | M22: Gross Profit - R&D - SG&A
C23: Interest income | D23: 0 | E23: 0 | F23: 0 | G23: =G156 -> 5112.0223 | H23: =H156 -> 6126.2494 | I23: =I156 -> 7340.2595 | J23: =J156 -> 8845.3404 | K23: =K156 -> 10663.488 | M23: Reference from interest on cash schedule
C24: Interest expense (enter as -) | D24: 0 | E24: 0 | F24: 0 | G24: =-G142 -> -3002.8831 | H24: =-H142 -> -3087.123 | I24: =-I142 -> -3087.123 | J24: =-J142 -> -3087.123 | K24: =-K142 -> -3087.123 | M24: Reference from interest expense schedule
C25: Other expense, net (enter as -) | D25: -565 | E25: 269 | F25: -321 | G25: =F25 -> -321 | H25: =G25 -> -321 | I25: =H25 -> -321 | J25: =I25 -> -321 | K25: =J25 -> -321 | M25: Straight-line
C26: Pretax profit | D26: =SUM(D22:D25) -> 113736 | E26: =SUM(E22:E25) -> 123485 | F26: =SUM(F22:F25) -> 132729 | G26: =SUM(G22:G25) -> 141490.64 | H26: =SUM(H22:H25) -> 149405.75 | I26: =SUM(I22:I25) -> 157954.14 | J26: =SUM(J22:J25) -> 167160.32 | K26: =SUM(K22:K25) -> 177064.63 | M26: EBIT + interest income less interest expense less other expense
C27: Taxes (enter expense as -) | D27: -16741 | E27: -29749 | F27: -20719 | G27: =-G40*G26 -> -22086.692 | H27: =-H40*H26 -> -23322.241 | I27: =-I40*I26 -> -24656.645 | J27: =-J40*J26 -> -26093.73 | K27: =-K40*K26 -> -27639.792 | M27: Pre-tax Profit x Tax Rate forecast
C28: Net income | D28: =SUM(D26:D27) -> 96995 | E28: =SUM(E26:E27) -> 93736 | F28: =SUM(F26:F27) -> 112010 | G28: =SUM(G26:G27) -> 119403.95 | H28: =SUM(H26:H27) -> 126083.51 | I28: =SUM(I26:I27) -> 133297.5 | J28: =SUM(J26:J27) -> 141066.59 | K28: =SUM(K26:K27) -> 149424.83 | M28: Pre-tax Profit less taxes
C30: Depreciation & amortization | D30: 11519 | E30: 11445 | F30: 11698 | G30: =G106 -> 12549.915 | H30: =H106 -> 13457.776 | I30: =I106 -> 14425.049 | J30: =J106 -> 15455.405 | K30: =K106 -> 16552.734 | M30: Reference from D&A schedule
C31: EBITDA | D31: =D22+D30 -> 125820 | E31: =E22+E30 -> 134661 | F31: =F22+F30 -> 144748 | G31: =G22+G30 -> 152252.42 | H31: =H22+H30 -> 160145.4 | I31: =I22+I30 -> 168447.06 | J31: =J22+J30 -> 177178.51 | K31: =K22+K30 -> 186362 | M31: EBIT + D&A
C32: Stock based compensation | D32: 10833 | E32: 11688 | F32: 12863 | G32: =F32*(1+G36) -> 13506.15 | H32: =G32*(1+H36) -> 14181.458 | I32: =H32*(1+I36) -> 14890.53 | J32: =I32*(1+J36) -> 15635.057 | K32: =J32*(1+K36) -> 16416.81 | M32: WSP assumption: grow SBC in-line with revenue growth
C33: Adjusted EBITDA | D33: =SUM(D31:D32) -> 136653 | E33: =SUM(E31:E32) -> 146349 | F33: =SUM(F31:F32) -> 157611 | G33: =SUM(G31:G32) -> 165758.57 | H33: =SUM(H31:H32) -> 174326.86 | I33: =SUM(I31:I32) -> 183337.59 | J33: =SUM(J31:J32) -> 192813.57 | K33: =SUM(K31:K32) -> 202778.81 | M33: EBITDA + Stock-based compensation
C35: Growth rates & margins
C36: Revenue growth | E36: =E17/D17-1 -> 0.020219941 | F36: =F17/E17-1 -> 0.064255118 | G36: 0.05 | H36: 0.05 | I36: 0.05 | J36: =I36 -> 0.05 | K36: =J36 -> 0.05 | M36: JP Morgan estimates through 2021; straight-line growth rate thereafter
C37: Gross profit margin | D37: =D19/D17 -> 0.4413113 | E37: =E19/E17 -> 0.4620635 | F37: =F19/F17 -> 0.46905164 | G37: =F37 -> 0.46905164 | H37: =G37 -> 0.46905164 | I37: =H37 -> 0.46905164 | J37: =I37 -> 0.46905164 | K37: =J37 -> 0.46905164 | M37: JP Morgan estimates through 2021; straight-line margin thereafter
C38: R&D % of sales | D38: =-D20/D17 -> 0.078048971 | E38: =-E20/E17 -> 0.080222998 | F38: =-F20/F17 -> 0.083020754 | G38: =F38 -> 0.083020754 | H38: =G38 -> 0.083020754 | I38: =H38 -> 0.083020754 | J38: =I38 -> 0.083020754 | K38: =J38 -> 0.083020754 | M38: JP Morgan estimates through 2021: straight-line margin thereafter
C39: SG&A % of sales | D39: =-D21/D17 -> 0.065048202 | E39: =-E21/E17 -> 0.066738272 | F39: =-F21/F17 -> 0.066322889 | G39: =F39 -> 0.066322889 | H39: =G39 -> 0.066322889 | I39: =H39 -> 0.066322889 | J39: =I39 -> 0.066322889 | K39: =J39 -> 0.066322889 | M39: JP Morgan estimates through 2021: straight-line margin thereafter
C40: Tax rate | D40: =-(D27/D26) -> 0.14719174 | E40: =-(E27/E26) -> 0.24091185 | F40: =-(F27/F26) -> 0.15610002 | G40: =F40 -> 0.15610002 | H40: =G40 -> 0.15610002 | I40: =H40 -> 0.15610002 | J40: =I40 -> 0.15610002 | K40: =J40 -> 0.15610002 | M40: JP Morgan estimates through 2021: straight-line margin thereafter
C42: BALANCE SHEET
C43: =C14 -> Fiscal year | E43: =E14 -> 2024 | F43: =F14 -> 2025 | G43: =G14 -> 2026 | H43: =H14 -> 2027 | I43: =I14 -> 2028 | J43: =J14 -> 2029 | K43: =K14 -> 2030
C44: =C15 -> Fiscal year end date | E44: =E15 -> 45565 | F44: =F15 -> 45927 | G44: =G15 -> 46295 | H44: =H15 -> 46660 | I44: =I15 -> 47026 | J44: =J15 -> 47391 | K44: =K15 -> 47756
C45: Cash & equivalents, ST and LT marketable securities | E45: =29943+35228+91479 -> 156650 | F45: =35934+18763+77723 -> 132420 | G45: =G90+F45 -> 159695.56 | H45: =H90+G45 -> 190375.83 | I45: =I90+H45 -> 229067.56 | J45: =J90+I45 -> 276380.46 | K45: =K90+J45 -> 332961.71 | M45: Reference from 'net change in cash' line on the cash flow statement
C46: Accounts receivable | E46: 33410 | F46: 39777 | G46: =F46*(1+G36) -> 41765.85 | H46: =G46*(1+H36) -> 43854.143 | I46: =H46*(1+I36) -> 46046.85 | J46: =I46*(1+J36) -> 48349.192 | K46: =J46*(1+K36) -> 50766.652 | M46: Grow in-line with revenue growth
C47: Inventories | E47: 7286 | F47: 5718 | G47: =F47*G18/F18 -> 6003.9 | H47: =G47*H18/G18 -> 6304.095 | I47: =H47*I18/H18 -> 6619.2998 | J47: =I47*J18/I18 -> 6950.2647 | K47: =J47*K18/J18 -> 7297.778 | M47: Grow in-line with cost of sales growth
...

Sheet Find the errors
C2: ="Financial Statement Model for "&D5 -> Financial Statement Model for Apple
C3: $ in thousands except per share
C5: Company name | D5: Apple
C6: Ticker | D6: AAPL
C7: Circ break 1=off, 0=on | D7: 1
C8: Latest closing share price | D8: 171.25
C9: Latest closing share price date | D9: 43500
C10: Latest fiscal year end date | D10: 43372
C11: Shares outstanding (millions) | D11: 4745.398
C13: INCOME STATEMENT
C14: Fiscal year | D14: =E14-1 -> 2016 | E14: =F14-1 -> 2017 | F14: =YEAR(D10) -> 2018 | G14: =F14+1 -> 2019 | H14: =G14+1 -> 2020 | I14: =H14+1 -> 2021 | J14: =I14+1 -> 2022 | K14: =J14+1 -> 2023
C15: Fiscal year end date | D15: =EOMONTH(E15,-12) -> 42643 | E15: =EOMONTH(F15,-12) -> 43008 | F15: =D10 -> 43372 | G15: =EOMONTH(F15,12) -> 43738 | H15: =EOMONTH(G15,12) -> 44104 | I15: =EOMONTH(H15,12) -> 44469 | J15: =EOMONTH(I15,12) -> 44834 | K15: =EOMONTH(J15,12) -> 45199 | M15: WSP Comments
C17: Revenue | D17: 215639 | E17: 229234 | F17: 265595 | G17: =F17*(1+G36) -> 254971.2 | H17: =G17*(1+H36) -> 270269.47 | I17: =H17*(1+I36) -> 288918.07 | J17: =I17*(1+J36) -> 308853.41 | K17: =J17*(1+K36) -> 330164.3 | M17: Previous year's revenues x (1+revenue growth rate)
C18: Cost of sales (enter as -) | D18: -131376 | E18: -141048 | F18: -163756 | G18: =G19-G17 -> -158592.09 | H18: =H19-H17 -> -167296.8 | I18: =I19-I17 -> -178551.36 | J18: =J19-J17 -> -190871.41 | K18: =K19-K17 -> -204041.54 | M18: Plug = Revenue - Gross Profit
C19: Gross Profit | D19: =SUM(D17:D18) -> 84263 | E19: =SUM(E17:E18) -> 88186 | F19: =SUM(F17:F18) -> 101839 | G19: =G17*G37 -> 96379.114 | H19: =H17*H37 -> 102972.67 | I19: =I17*I37 -> 110366.7 | J19: =J17*J37 -> 117982 | K19: =K17*K37 -> 126122.76 | M19: Revenue x Gross Profit Margin forecast
C20: Research & development (enter as -) | D20: -10045 | E20: -11581 | F20: -14236 | G20: =-G38*G17 -> -15808.214 | H20: =-H38*H17 -> -17026.977 | I20: =-I38*I17 -> -18201.838 | J20: =-J38*J17 -> -19457.765 | K20: =-K38*K17 -> -20800.351 | M20: Revenue x R&D % of sales forecast
C21: Selling, general & administrative (enter as -) | D21: -14194 | E21: -15261 | F21: -16705 | G21: =-G17*G39 -> -18867.869 | H21: =-H17*H39 -> -18648.594 | I21: =-I17*I39 -> -19935.347 | J21: =-J17*J39 -> -21310.885 | K21: =-K17*K39 -> -22781.337 | M21: Revenue x SG&A % of sales forecast
C22: Operating profit (EBIT) | D22: =D19+D20+D21 -> 60024 | E22: =E19+E20+E21 -> 61344 | F22: =F19+F20+F21 -> 70898 | G22: =G19+G20+G21 -> 61703.03 | H22: =H19+H20+H21 -> 67297.099 | I22: =I19+I20+I21 -> 72229.516 | J22: =J19+J20+J21 -> 77213.353 | K22: =K19+K20+K21 -> 82541.074 | M22: Gross Profit - R&D - SG&A
C23: Interest income | D23: 3999 | E23: 5201 | F23: 5686 | G23: =G156 -> 4854.9195 | H23: =H156 -> 4561.8995 | I23: =I156 -> 4589.125 | J23: =J156 -> 4760.1829 | K23: =K156 -> 5062.6676 | M23: Reference from interest on cash schedule
C24: Interest expense (enter as -) | D24: -1456 | E24: -2323 | F24: -3240 | G24: =-G142 -> -3223.1469 | H24: =-H142 -> -3223.5393 | I24: =-I142 -> -3223.5393 | J24: =-J142 -> -3223.5393 | K24: =-K142 -> -3223.5393 | M24: Reference from interest expense schedule
C25: Other expense, net (enter as -) | D25: -1195 | E25: -133 | F25: -441 | G25: =F25 -> -441 | H25: =G25 -> -441 | I25: =H25 -> -441 | J25: =I25 -> -441 | K25: =J25 -> -441 | M25: Straight-line
C26: Pretax profit | D26: =SUM(D22:D25) -> 61372 | E26: =SUM(E22:E25) -> 64089 | F26: =SUM(F22:F25) -> 72903 | G26: =SUM(G22:G25) -> 62893.803 | H26: =SUM(H22:H25) -> 68194.459 | I26: =SUM(I22:I25) -> 73154.102 | J26: =SUM(J22:J25) -> 78308.997 | K26: =SUM(K22:K25) -> 83939.203 | M26: EBIT + interest income less interest expense less other expense
C27: Taxes (enter expense as -) | D27: -15685 | E27: -15738 | F27: -13372 | G27: =-G40*G26 -> -10503.265 | H27: =-H40*H26 -> -11593.058 | I27: =-I40*I26 -> -12363.043 | J27: =-J40*J26 -> -13234.22 | K27: =-K40*K26 -> -14185.725 | M27: Pre-tax Profit x Tax Rate forecast
C28: Net income | D28: =SUM(D26:D27) -> 45687 | E28: =SUM(E26:E27) -> 48351 | F28: =SUM(F26:F27) -> 59531 | G28: =SUM(G26:G27) -> 52390.538 | H28: =SUM(H26:H27) -> 56601.401 | I28: =SUM(I26:I27) -> 60791.059 | J28: =SUM(J26:J27) -> 65074.776 | K28: =SUM(K26:K27) -> 69753.477 | M28: Pre-tax Profit less taxes
C30: Depreciation & amortization | D30: 10505 | E30: 10157 | F30: 10903 | G30: =G106 -> 11085.02 | H30: =H106 -> 11711.891 | I30: =I106 -> 12226.381 | J30: =J106 -> 13365.451 | K30: =K106 -> 14603.503 | M30: Reference from D&A schedule
C31: EBITDA | D31: =D22+D30 -> 70529 | E31: =E22+E30 -> 71501 | F31: =F22+F30 -> 81801 | G31: =G22+G30 -> 72788.051 | H31: =H22+H30 -> 79008.989 | I31: =I22+I30 -> 84455.897 | J31: =J22+J30 -> 90578.804 | K31: =K22+K30 -> 97144.578 | M31: EBIT + D&A
C32: Stock based compensation | D32: 4210 | E32: 4840 | F32: 5340 | G32: =F32*(1+G36) -> 5126.4 | H32: =G32*(1+H36) -> 5433.984 | I32: =H32*(1+I36) -> 5808.9289 | J32: =I32*(1+J36) -> 6209.745 | K32: =J32*(1+K36) -> 6638.2174 | M32: WSP assumption: grow SBC in-line with revenue growth
C33: Adjusted EBITDA | D33: =SUM(D31:D32) -> 74739 | E33: =SUM(E31:E32) -> 76341 | F33: =SUM(F31:F32) -> 87141 | G33: =SUM(G31:G32) -> 77914.451 | H33: =SUM(H31:H32) -> 84442.973 | I33: =SUM(I31:I32) -> 90264.826 | J33: =SUM(J31:J32) -> 96788.549 | K33: =SUM(K31:K32) -> 103782.8 | M33: EBITDA + Stock-based compensation
C35: Growth rates & margins
C36: Revenue growth | E36: =E17/D17-1 -> 0.063045182 | F36: =F17/E17-1 -> 0.15861958 | G36: -0.04 | H36: 0.06 | I36: 0.069 | J36: =I36 -> 0.069 | K36: =J36 -> 0.069 | M36: JP Morgan estimates through 2021; straight-line growth rate thereafter
C37: Gross profit margin | D37: =D19/D17 -> 0.39075956 | E37: =E19/E17 -> 0.3846986 | F37: =F19/F17 -> 0.38343719 | G37: 0.378 | H37: 0.381 | I37: 0.382 | J37: =I37 -> 0.382 | K37: =J37 -> 0.382 | M37: JP Morgan estimates through 2021; straight-line margin thereafter
C38: R&D % of sales | D38: =-D20/D17 -> 0.046582483 | E38: =-E20/E17 -> 0.050520429 | F38: =-F20/F17 -> 0.053600407 | G38: 0.062 | H38: 0.063 | I38: 0.063 | J38: =I38 -> 0.063 | K38: =J38 -> 0.063 | M38: JP Morgan estimates through 2021: straight-line margin thereafter
C39: SG&A % of sales | D39: =-D21/D17 -> 0.065822973 | E39: =-E21/E17 -> 0.066573894 | F39: =-F21/F17 -> 0.062896515 | G39: 0.074 | H39: 0.069 | I39: 0.069 | J39: =I39 -> 0.069 | K39: =J39 -> 0.069 | M39: JP Morgan estimates through 2021: straight-line margin thereafter
C40: Tax rate | D40: =-(D27/D26) -> 0.25557257 | E40: =-(E27/E26) -> 0.24556476 | F40: =-(F27/F26) -> 0.18342181 | G40: 0.167 | H40: 0.17 | I40: 0.169 | J40: =I40 -> 0.169 | K40: =J40 -> 0.169 | M40: JP Morgan estimates through 2021: straight-line margin thereafter
C42: BALANCE SHEET
C43: =C14 -> Fiscal year | E43: =E14 -> 2017 | F43: =F14 -> 2018 | G43: =G14 -> 2019 | H43: =H14 -> 2020 | I43: =I14 -> 2021 | J43: =J14 -> 2022 | K43: =K14 -> 2023
C44: =C15 -> Fiscal year end date | E44: =E15 -> 43008 | F44: =F15 -> 43372 | G44: =G15 -> 43738 | H44: =H15 -> 44104 | I44: =I15 -> 44469 | J44: =J15 -> 44834 | K44: =K15 -> 45199
C45: Cash & equivalents, ST and LT marketable securities | E45: =20289+53892+194714 -> 268895 | F45: =25913+40388+170799 -> 237100 | G45: =G90+F45 -> 212429.59 | H45: =H90+G45 -> 209968.51 | I45: =I90+H45 -> 214950.47 | J45: =J90+I45 -> 225807.21 | K45: =K90+J45 -> 242958.31 | M45: Reference from 'net change in cash' line on the cash flow statement
C46: Accounts receivable | E46: 17874 | F46: 23186 | G46: =F46*(1+G36) -> 22258.56 | H46: =G46*(1+H36) -> 23594.074 | I46: =H46*(1+I36) -> 25222.065 | J46: =I46*(1+J36) -> 26962.387 | K46: =J46*(1+K36) -> 28822.792 | M46: Grow in-line with revenue growth
C47: Inventories | E47: 4855 | F47: 3956 | G47: =F47*G18/F18 -> 3831.2507 | H47: =G47*H18/G18 -> 4041.5383 | I47: =H47*I18/H18 -> 4313.4248 | J47: =I47*J18/I18 -> 4611.0512 | K47: =J47*K18/J18 -> 4929.2137 | M47: Grow in-line with cost of sales growth
...

Sheet Find the errors Complete
C2: ="Financial Statement Model for "&D5 -> Financial Statement Model for Apple
C3: $ in thousands except per share
C5: Company name | D5: Apple
C6: Ticker | D6: AAPL
C7: Circ break 1=off, 0=on | D7: 1
C8: Latest closing share price | D8: 171.25
C9: Latest closing share price date | D9: 43500
C10: Latest fiscal year end date | D10: 43372
C11: Shares outstanding (millions) | D11: 4745.398
C13: INCOME STATEMENT
C14: Fiscal year | D14: =E14-1 -> 2016 | E14: =F14-1 -> 2017 | F14: =YEAR(D10) -> 2018 | G14: =F14+1 -> 2019 | H14: =G14+1 -> 2020 | I14: =H14+1 -> 2021 | J14: =I14+1 -> 2022 | K14: =J14+1 -> 2023
C15: Fiscal year end date | D15: =EOMONTH(E15,-12) -> 42643 | E15: =EOMONTH(F15,-12) -> 43008 | F15: =D10 -> 43372 | G15: =EOMONTH(F15,12) -> 43738 | H15: =EOMONTH(G15,12) -> 44104 | I15: =EOMONTH(H15,12) -> 44469 | J15: =EOMONTH(I15,12) -> 44834 | K15: =EOMONTH(J15,12) -> 45199 | M15: WSP Comments
C17: Revenue | D17: 215639 | E17: 229234 | F17: 265595 | G17: =F17*(1+G36) -> 254971.2 | H17: =G17*(1+H36) -> 270269.47 | I17: =H17*(1+I36) -> 288918.07 | J17: =I17*(1+J36) -> 308853.41 | K17: =J17*(1+K36) -> 330164.3 | M17: Previous year's revenues x (1+revenue growth rate)
C18: Cost of sales (enter as -) | D18: -131376 | E18: -141048 | F18: -163756 | G18: =G19-G17 -> -158592.09 | H18: =H19-H17 -> -167296.8 | I18: =I19-I17 -> -178551.36 | J18: =J19-J17 -> -190871.41 | K18: =K19-K17 -> -204041.54 | M18: Plug = Revenue - Gross Profit
